<?xml version="1.0" ?>
<!-- =================================================================================== -->
<!-- |    This document was autogenerated by xacro from myrobot.xacro                  | -->
<!-- |    EDITING THIS FILE BY HAND IS NOT RECOMMENDED                                 | -->
<!-- =================================================================================== -->
<robot name="myrobot">
  <link name="base_link">
    <inertial>
      <origin rpy="0.0 0.0 0.0" xyz="0.0 0.0 0.0"/>
      <mass value="5.0"/>
      <inertia ixx="0.0" ixy="0.0" ixz="0.0" iyy="0.0" iyz="0.0" izz="0.0"/>
    </inertial>
    <visual>
      <origin rpy="0.0 0.0 0.0" xyz="0.0 0.0 0.0"/>
      <geometry>
        <cylinder length="0.15" radius="0.25"/>
      </geometry>
      <material name="red">
        <color rgba="1.0 0.0 0.0 1.0"/>
      </material>
    </visual>
    <collision>
      <origin rpy="0.0 0.0 0.0" xyz="0.0 0.0 0.0"/>
      <geometry>
        <cylinder length="0.15" radius="0.5"/>
      </geometry>
    </collision>
  </link>
  <link name="left_wheel">
    <inertial>
      <origin rpy="0.0 0.0 0.0" xyz="0.0 0.0 0.0"/>
      <mass value="1.0"/>
      <inertia ixx="0.001" ixy="0.0" ixz="0.0" iyy="0.001" iyz="0.0" izz="0.001"/>
    </inertial>
    <visual>
      <origin rpy="0.0 0.0 0.0" xyz="0.0 0.0 0.0"/>
      <geometry>
        <cylinder length="0.07" radius="0.1"/>
      </geometry>
      <material name="black">
        <color rgba="0.0 0.0 0.0 1.0"/>
      </material>
    </visual>
    <collision>
      <origin rpy="0.0 0.0 0.0" xyz="0.0 0.0 0.0"/>
      <geometry>
        <cylinder length="0.07" radius="0.1"/>
      </geometry>
    </collision>
  </link>
  <link name="right_wheel">
    <inertial>
      <origin rpy="0.0 0.0 0.0" xyz="0.0 0.0 0.0"/>
      <mass value="1.0"/>
      <inertia ixx="0.001" ixy="0.0" ixz="0.0" iyy="0.001" iyz="0.0" izz="0.001"/>
    </inertial>
    <visual name="right_wheel_visual">
      <origin rpy="0.0 0.0 0.0" xyz="0.0 0.0 0.0"/>
      <geometry>
        <cylinder length="0.07" radius="0.1"/>
      </geometry>
      <material name="black">
        <color rgba="0.0 0.0 0.0 1.0"/>
        <texture filename=""/>
      </material>
    </visual>
    <collision>
      <origin rpy="0.0 0.0 0.0" xyz="0.0 0.0 0.0"/>
      <geometry>
        <cylinder length="0.07" radius="0.1"/>
      </geometry>
    </collision>
  </link>
  <joint name="left_wheel_joint" type="continuous">
    <origin rpy="0.0 1.5707 1.5707" xyz="0.065 0.15 -0.05"/>
    <parent link="base_link"/>
    <child link="left_wheel"/>
    <axis xyz="0.0 0.0 1.0"/>
  </joint>
  <joint name="right_wheel_joint" type="continuous">
    <origin rpy="0.0 1.5707 1.5707" xyz="0.065 -0.15 -0.05"/>
    <parent link="base_link"/>
    <child link="right_wheel"/>
    <axis xyz="0.0 0.0 1.0"/>
  </joint>
  <link name="caster_wheel">
    <inertial>
      <mass value="0.2"/>
      <origin rpy="0 0 0" xyz="0 0 0"/>
      <inertia ixx="0.001" ixy="0.0" ixz="0.0" iyy="0.001" iyz="0.0" izz="0.001"/>
    </inertial>
    <visual>
      <origin rpy="0 0 0" xyz="0 0 0"/>
      <geometry>
        <sphere radius="0.05"/>
      </geometry>
      <material name="gray">
        <color rgba="0.5 0.5 0.5 1"/>
      </material>
    </visual>
    <collision>
      <origin rpy="0 0 0" xyz="0 0 0"/>
      <geometry>
        <sphere radius="0.05"/>
      </geometry>
    </collision>
  </link>
  <joint name="caster_wheel_joint" type="fixed">
    <parent link="base_link"/>
    <child link="caster_wheel"/>
    <origin rpy="0 0 0" xyz="-0.15 0 -0.1"/>
  </joint>
</robot>

