<?xml version="1.0"?>
<robot xmlns:xacro="http://www.ros.org/wiki/xacro" name="myrobot">

  <link name="base_link">
      <inertial>
          <origin xyz="0.0 0.0 0.0" rpy="0.0 0.0 0.0"/>
          <mass value="5.0"/>
          <inertia ixx="0.0" ixy="0.0" ixz="0.0" iyy="0.0" iyz="0.0" izz="0.0"/>
      </inertial>
      <visual>
          <origin xyz="0.0 0.0 0.0" rpy="0.0 0.0 0.0"/>
          <geometry>
             <cylinder radius="0.25" length="0.15"/>
          </geometry>
          <material name="red">
              <color rgba="1.0 0.0 0.0 1.0"/>
          </material>
      </visual>
      <collision>
          <origin xyz="0.0 0.0 0.0" rpy="0.0 0.0 0.0"/>
          <geometry>
             <cylinder radius="0.5" length="0.15"/>
          </geometry>
      </collision>
  </link>

    <link name="left_wheel">
      <inertial>
          <origin xyz="0.0 0.0 0.0" rpy="0.0 0.0 0.0"/>
          <mass value="1.0"/>
          <inertia ixx="0.001" ixy="0.0" ixz="0.0" iyy="0.001" iyz="0.0" izz="0.001"/>
      </inertial>
      <visual>
          <origin xyz="0.0 0.0 0.0" rpy="0.0 0.0 0.0"/>
          <geometry>
              <cylinder radius="0.1" length="0.07"/>
          </geometry>
          <material name="black">
              <color rgba="0.0 0.0 0.0 1.0"/>
          </material>
      </visual>
      <collision>
          <origin xyz="0.0 0.0 0.0" rpy="0.0 0.0 0.0"/>
          <geometry>
              <cylinder radius="0.1" length="0.07"/>
          </geometry>
      </collision>
  </link>

  <link name="right_wheel">
    <inertial>
        <origin xyz="0.0 0.0 0.0" rpy="0.0 0.0 0.0"/>
        <mass value="1.0"/>
        <inertia ixx="0.001" ixy="0.0" ixz="0.0" iyy="0.001" iyz="0.0" izz="0.001"/>
    </inertial>
    <visual name="right_wheel_visual">
        <origin xyz="0.0 0.0 0.0" rpy="0.0 0.0 0.0"/>
        <geometry>
          <cylinder radius="0.1" length="0.07"/>
        </geometry>
        <material name="black">
            <color rgba="0.0 0.0 0.0 1.0"/>
            <texture filename=""/>
        </material>
    </visual>
    <collision>
        <origin xyz="0.0 0.0 0.0" rpy="0.0 0.0 0.0"/>
        <geometry>
            <cylinder radius="0.1" length="0.07"/>
        </geometry>
    </collision>
  </link>

  <joint name="left_wheel_joint" type="continuous">
    <origin xyz="0.065 0.15 -0.05" rpy="0.0 1.5707 1.5707"/>
    <parent link="base_link"/>
    <child link="left_wheel"/>
    <axis xyz="0.0 0.0 1.0"/>
  </joint>

  <joint name="right_wheel_joint" type="continuous">
    <origin xyz="0.065 -0.15 -0.05" rpy="0.0 1.5707 1.5707"/>
    <parent link="base_link"/>
    <child link="right_wheel"/>
    <axis xyz="0.0 0.0 1.0"/>
  </joint>

  <link name="caster_wheel">
      <inertial>
          <mass value="0.2"/>
          <origin xyz="0 0 0" rpy="0 0 0"/>
          <inertia ixx="0.001" ixy="0.0" ixz="0.0" iyy="0.001" iyz="0.0" izz="0.001"/>
      </inertial>
      <visual>
          <origin xyz="0 0 0" rpy="0 0 0"/>
          <geometry>
              <sphere radius="0.05"/>
          </geometry>
          <material name="gray">
              <color rgba="0.5 0.5 0.5 1"/>
          </material>
      </visual>
      <collision>
          <origin xyz="0 0 0" rpy="0 0 0"/>
          <geometry>
              <sphere radius="0.05"/>
          </geometry>
      </collision>
  </link>

  <joint name="caster_wheel_joint" type="fixed">
      <parent link="base_link"/>
      <child link="caster_wheel"/>
      <origin xyz="-0.15 0 -0.1" rpy="0 0 0"/>
  </joint>

</robot>